{
 "cells": [
  {
   "cell_type": "markdown",
   "id": "9e0671fc-0a00-45aa-b42f-02a15ecc88ec",
   "metadata": {},
   "source": [
    "## Q1. What is an Exception in python? Write the difference between Exceptions and Syntax errors."
   ]
  },
  {
   "cell_type": "markdown",
   "id": "67b61717-3fe4-4fbe-bca0-5aa6e3772921",
   "metadata": {},
   "source": [
    "In Python, an Exception is an error that occurs during the execution of a program. When an Exception occurs, the program stops executing and Python raises an error message that describes the type of exception that occurred and the line of code where the exception occurred.\n",
    "\n",
    "Exceptions can occur for a variety of reasons, such as when a program tries to perform an operation on data that is not the expected type or when a program tries to access a resource that is not available. Python provides a set of built-in Exception classes that can be used to handle different types of exceptions.\n",
    "\n",
    "Syntax errors, on the other hand, occur when there is a problem with the syntax of the Python code itself. These errors occur before the program is executed and are caught by the Python interpreter before the code is run. Examples of syntax errors include forgetting to close a parentheses or a quotation mark, or using an incorrect keyword or operator.\n",
    "\n",
    "Here's an example that demonstrates the difference between Exceptions and Syntax errors:"
   ]
  },
  {
   "cell_type": "code",
   "execution_count": 3,
   "id": "f58208ec-df5e-42ca-860c-11b49ed649c0",
   "metadata": {},
   "outputs": [
    {
     "ename": "SyntaxError",
     "evalue": "invalid syntax. Maybe you meant '==' or ':=' instead of '='? (3298073927.py, line 9)",
     "output_type": "error",
     "traceback": [
      "\u001b[0;36m  Cell \u001b[0;32mIn[3], line 9\u001b[0;36m\u001b[0m\n\u001b[0;31m    if b = 5:\u001b[0m\n\u001b[0m       ^\u001b[0m\n\u001b[0;31mSyntaxError\u001b[0m\u001b[0;31m:\u001b[0m invalid syntax. Maybe you meant '==' or ':=' instead of '='?\n"
     ]
    }
   ],
   "source": [
    "# Example of an Exception\n",
    "try:\n",
    "    a = 10 / 0\n",
    "except ZeroDivisionError:\n",
    "    print(\"Error: Division by zero\")\n",
    "\n",
    "# Example of a Syntax error\n",
    "b = 10\n",
    "if b = 5:\n",
    "    print(\"b is equal to 5\")\n"
   ]
  },
  {
   "cell_type": "markdown",
   "id": "6c3ab895-6cb6-42a4-bc1d-9fc4d355e9a4",
   "metadata": {},
   "source": [
    "In the first example, we try to divide the number 10 by 0, which is not allowed. This causes a ZeroDivisionError Exception to be raised, which we catch and handle by printing an error message.\n",
    "\n",
    "In the second example, we have a syntax error in the if statement, where we are using the assignment operator (=) instead of the equality operator (==). This causes a syntax error, which is caught by the Python interpreter and prevents the program from executing.\n",
    "\n",
    "In summary, Exceptions are errors that occur during the execution of a program, while Syntax errors are errors that occur before the program is executed, due to problems with the syntax of the Python code itself."
   ]
  },
  {
   "cell_type": "markdown",
   "id": "7f76f13b-603c-4674-9775-077ec8c8f616",
   "metadata": {},
   "source": [
    "## Q2. What happens when an exception is not handled? Explain with an example"
   ]
  },
  {
   "cell_type": "markdown",
   "id": "a9cd1c56-baed-42b4-b954-55a94614a6ae",
   "metadata": {},
   "source": [
    "When an exception is not handled in a Python program, it will cause the program to terminate and an error message will be displayed that describes the type of exception that occurred and the line of code where the exception occurred.\n",
    "\n",
    "Here's an example that demonstrates what happens when an exception is not handled:"
   ]
  },
  {
   "cell_type": "code",
   "execution_count": 4,
   "id": "99409b8e-0ce4-4e13-8f6e-ff06f12ecfcc",
   "metadata": {},
   "outputs": [
    {
     "ename": "ZeroDivisionError",
     "evalue": "division by zero",
     "output_type": "error",
     "traceback": [
      "\u001b[0;31m---------------------------------------------------------------------------\u001b[0m",
      "\u001b[0;31mZeroDivisionError\u001b[0m                         Traceback (most recent call last)",
      "Cell \u001b[0;32mIn[4], line 2\u001b[0m\n\u001b[1;32m      1\u001b[0m \u001b[38;5;66;03m# Example of an unhandled exception\u001b[39;00m\n\u001b[0;32m----> 2\u001b[0m a \u001b[38;5;241m=\u001b[39m \u001b[38;5;241;43m10\u001b[39;49m\u001b[43m \u001b[49m\u001b[38;5;241;43m/\u001b[39;49m\u001b[43m \u001b[49m\u001b[38;5;241;43m0\u001b[39;49m\n\u001b[1;32m      3\u001b[0m \u001b[38;5;28mprint\u001b[39m(\u001b[38;5;124m\"\u001b[39m\u001b[38;5;124mResult: \u001b[39m\u001b[38;5;124m\"\u001b[39m, a)\n",
      "\u001b[0;31mZeroDivisionError\u001b[0m: division by zero"
     ]
    }
   ],
   "source": [
    "# Example of an unhandled exception\n",
    "a = 10 / 0\n",
    "print(\"Result: \", a)\n"
   ]
  },
  {
   "cell_type": "markdown",
   "id": "b665adaa-0a5e-4ce6-b1f6-4fd7307981d5",
   "metadata": {},
   "source": [
    "As we can see from the error message, Python tells us that a ZeroDivisionError occurred and that it was caused by a division by zero on line 1 of the code. The \"Traceback\" section of the error message shows the sequence of function calls that led to the exception.\n",
    "\n",
    "In summary, if an exception is not handled in a Python program, it will cause the program to terminate and display an error message that describes the type of exception that occurred and the line of code where the exception occurred. It's important to handle exceptions in your code to prevent unexpected program termination and to provide a graceful way to handle errors."
   ]
  },
  {
   "cell_type": "markdown",
   "id": "52a6359a-2a4b-4838-9d76-ee0e38f88072",
   "metadata": {},
   "source": [
    "## Q3. Which Python statements are used to catch and handle exceptions? Explain with an example"
   ]
  },
  {
   "cell_type": "markdown",
   "id": "6f47b734-f5ee-427a-8695-eacc44dd10b2",
   "metadata": {},
   "source": [
    "In Python, the try and except statements are used to catch and handle exceptions. The try statement is used to enclose a block of code that might raise an exception, while the except statement is used to specify how to handle the exception if one is raised.\n",
    "\n",
    "Here's an example that demonstrates how to catch and handle an exception in Python using try and except:"
   ]
  },
  {
   "cell_type": "code",
   "execution_count": 5,
   "id": "93cd4b8b-763b-444f-adf6-5675e8dd86fc",
   "metadata": {},
   "outputs": [
    {
     "name": "stdout",
     "output_type": "stream",
     "text": [
      "Error: Division by zero\n"
     ]
    }
   ],
   "source": [
    "try:\n",
    "    a = 10 / 0\n",
    "except ZeroDivisionError:\n",
    "    print(\"Error: Division by zero\")\n"
   ]
  },
  {
   "cell_type": "markdown",
   "id": "9820e9df-1b4d-4696-84ed-06627cdd9010",
   "metadata": {},
   "source": [
    "## Q4. Explain with an example:\n",
    "a. try and else\n",
    "b. finally\n",
    "c. raise"
   ]
  },
  {
   "cell_type": "markdown",
   "id": "6deb2c25-32fd-4640-b96e-edadd10e708a",
   "metadata": {},
   "source": [
    "In Python, the try statement can be followed by an optional else block. The else block is executed only if the try block does not raise an exception. It is often used to specify code that should be executed regardless of whether an exception occurred or not. Here's an example:\n",
    "\n",
    "python\n",
    "Copy code\n",
    "try:"
   ]
  },
  {
   "cell_type": "code",
   "execution_count": 6,
   "id": "5dac2ec1-62d7-4304-9541-494ec2fe0221",
   "metadata": {},
   "outputs": [
    {
     "name": "stdout",
     "output_type": "stream",
     "text": [
      "a = 2.0\n"
     ]
    }
   ],
   "source": [
    "try:\n",
    "    a = 10 / 5\n",
    "except ZeroDivisionError:\n",
    "    print(\"Error: Division by zero\")\n",
    "else:\n",
    "    print(\"a =\", a)\n"
   ]
  },
  {
   "cell_type": "markdown",
   "id": "2eac0fcd-add2-407b-9526-bdefbcd9eadd",
   "metadata": {},
   "source": [
    "b. finally:\n",
    "\n",
    "In Python, the finally block can be used to specify code that should be executed regardless of whether an exception was raised or not. The finally block is always executed, even if an exception occurred and was caught by an except block. Here's an example:"
   ]
  },
  {
   "cell_type": "code",
   "execution_count": 7,
   "id": "56bb82be-742e-4169-8f4b-123e902d99e8",
   "metadata": {},
   "outputs": [
    {
     "name": "stdout",
     "output_type": "stream",
     "text": [
      "Line 1\n",
      "Line 2\n",
      "Line 3\n",
      "\n"
     ]
    }
   ],
   "source": [
    "try:\n",
    "    file = open(\"example.txt\", \"r\")\n",
    "    contents = file.read()\n",
    "    print(contents)\n",
    "except FileNotFoundError:\n",
    "    print(\"Error: File not found\")\n",
    "finally:\n",
    "    file.close()\n"
   ]
  },
  {
   "cell_type": "markdown",
   "id": "d9242c11-00b7-42da-b7c3-fe0271c78bd4",
   "metadata": {},
   "source": [
    "c. raise:\n",
    "\n",
    "In Python, the raise statement can be used to raise an exception manually. It is often used to indicate that an error has occurred and to stop the execution of the program. Here's an example:"
   ]
  },
  {
   "cell_type": "code",
   "execution_count": 8,
   "id": "4652ef65-0b76-4764-9431-359d945d8c15",
   "metadata": {},
   "outputs": [
    {
     "name": "stdout",
     "output_type": "stream",
     "text": [
      "Error: Division by zero\n"
     ]
    }
   ],
   "source": [
    "def divide(a, b):\n",
    "    if b == 0:\n",
    "        raise ZeroDivisionError(\"Error: Division by zero\")\n",
    "    else:\n",
    "        return a / b\n",
    "\n",
    "try:\n",
    "    result = divide(10, 0)\n",
    "except ZeroDivisionError as e:\n",
    "    print(e)\n"
   ]
  },
  {
   "cell_type": "markdown",
   "id": "725ce1b8-5343-425a-9cd6-9d0f8ccd8f22",
   "metadata": {},
   "source": [
    "## Q5. What are Custom Exceptions in python? Why do we need Custom Exceptions? Explain with an example"
   ]
  },
  {
   "cell_type": "markdown",
   "id": "a2626eef-9a97-4f7b-863d-9105749301b2",
   "metadata": {},
   "source": [
    "In Python, custom exceptions can be defined by creating a new class that inherits from the built-in Exception class. These custom exceptions can be used to represent specific error conditions that are not covered by the built-in exceptions, and can provide more specific information about what went wrong in the code.\n",
    "\n",
    "We need custom exceptions in Python when we want to raise exceptions that are specific to our own code or application. By creating custom exceptions, we can give more meaningful error messages and provide better feedback to the user. This can help with debugging and troubleshooting, and can make our code more readable and maintainable.\n",
    "\n",
    "Here's an example of how to create a custom exception in Python:"
   ]
  },
  {
   "cell_type": "code",
   "execution_count": 9,
   "id": "1ecd4166-6c05-4a1d-a14f-b5a4f3a44d8a",
   "metadata": {},
   "outputs": [
    {
     "name": "stdout",
     "output_type": "stream",
     "text": [
      "Error: Negative number not allowed: -5\n"
     ]
    }
   ],
   "source": [
    "class NegativeNumberError(Exception):\n",
    "    def __init__(self, number):\n",
    "        self.number = number\n",
    "        self.message = \"Error: Negative number not allowed\"\n",
    "        super().__init__(self.message)\n",
    "\n",
    "    def __str__(self):\n",
    "        return f\"{self.message}: {self.number}\"\n",
    "\n",
    "def divide(a, b):\n",
    "    if b < 0:\n",
    "        raise NegativeNumberError(b)\n",
    "    else:\n",
    "        return a / b\n",
    "\n",
    "try:\n",
    "    result = divide(10, -5)\n",
    "except NegativeNumberError as e:\n",
    "    print(e)\n"
   ]
  },
  {
   "cell_type": "markdown",
   "id": "bad3293c-2097-49b5-9eee-d069a37bc7d0",
   "metadata": {},
   "source": [
    "## Q6. Create custom exception class. Use this class to handle an exception."
   ]
  },
  {
   "cell_type": "code",
   "execution_count": 10,
   "id": "4dba0de3-789a-4220-a66f-571f898806fc",
   "metadata": {},
   "outputs": [
    {
     "name": "stdout",
     "output_type": "stream",
     "text": [
      "Error: Division by zero not allowed\n"
     ]
    }
   ],
   "source": [
    "class CustomException(Exception):\n",
    "    def __init__(self, message):\n",
    "        self.message = message\n",
    "        super().__init__(self.message)\n",
    "\n",
    "def divide(a, b):\n",
    "    if b == 0:\n",
    "        raise CustomException(\"Error: Division by zero not allowed\")\n",
    "    else:\n",
    "        return a / b\n",
    "\n",
    "try:\n",
    "    result = divide(10, 0)\n",
    "except CustomException as e:\n",
    "    print(e.message)\n"
   ]
  },
  {
   "cell_type": "code",
   "execution_count": null,
   "id": "0bfc9955-1aa3-4f6c-9ada-9b5ef0e74085",
   "metadata": {},
   "outputs": [],
   "source": []
  }
 ],
 "metadata": {
  "kernelspec": {
   "display_name": "Python 3 (ipykernel)",
   "language": "python",
   "name": "python3"
  },
  "language_info": {
   "codemirror_mode": {
    "name": "ipython",
    "version": 3
   },
   "file_extension": ".py",
   "mimetype": "text/x-python",
   "name": "python",
   "nbconvert_exporter": "python",
   "pygments_lexer": "ipython3",
   "version": "3.10.8"
  }
 },
 "nbformat": 4,
 "nbformat_minor": 5
}
